Traceback (most recent call last):
  File "C:\Users\artem.tyubaev\Downloads\SKAMEYKA-main\callback.py", line 534, in UpdateDict
    sql = f"INSERT INTO skameyka.user_table (username, password, fullname, relevant, admin) VALUES " \
KeyError: 'UserLogin'
Traceback (most recent call last):
  File "C:\Users\artem.tyubaev\Downloads\SKAMEYKA-main\callback.py", line 534, in UpdateDict
    sql = f"INSERT INTO skameyka.user_table (username, password, fullname, relevant, admin) VALUES " \
KeyError: 'UserLogin'
Traceback (most recent call last):
  File "C:\Users\Asus\PycharmProjects\SKAMEYKA\callback.py", line 548, in UpdateDict
    sql = f"INSERT INTO skameyka.project_table (title, stage, code, customer, relevant) VALUES " \
KeyError: 'PrjStage'
Traceback (most recent call last):
  File "C:\Python 37\lib\site-packages\sqlalchemy\engine\base.py", line 1277, in _execute_context
    cursor, statement, parameters, context
  File "C:\Python 37\lib\site-packages\sqlalchemy\engine\default.py", line 608, in do_execute
    cursor.execute(statement, parameters)
  File "C:\Python 37\lib\site-packages\pymysql\cursors.py", line 148, in execute
    result = self._query(query)
  File "C:\Python 37\lib\site-packages\pymysql\cursors.py", line 310, in _query
    conn.query(q)
  File "C:\Python 37\lib\site-packages\pymysql\connections.py", line 548, in query
    self._affected_rows = self._read_query_result(unbuffered=unbuffered)
  File "C:\Python 37\lib\site-packages\pymysql\connections.py", line 775, in _read_query_result
    result.read()
  File "C:\Python 37\lib\site-packages\pymysql\connections.py", line 1156, in read
    first_packet = self.connection._read_packet()
  File "C:\Python 37\lib\site-packages\pymysql\connections.py", line 725, in _read_packet
    packet.raise_for_error()
  File "C:\Python 37\lib\site-packages\pymysql\protocol.py", line 221, in raise_for_error
    err.raise_mysql_exception(self._data)
  File "C:\Python 37\lib\site-packages\pymysql\err.py", line 143, in raise_mysql_exception
    raise errorclass(errno, errval)
pymysql.err.IntegrityError: (1062, "Duplicate entry '1-2-2021-09-28 00:00:00' for key 'main_table.PRIMARY'")

The above exception was the direct cause of the following exception:

Traceback (most recent call last):
  File "C:\Users\Asus\PycharmProjects\SKAMEYKA\callback.py", line 200, in SaveCalendar
    con.execute(sql)
  File "C:\Python 37\lib\site-packages\sqlalchemy\engine\base.py", line 1003, in execute
    return self._execute_text(object_, multiparams, params)
  File "C:\Python 37\lib\site-packages\sqlalchemy\engine\base.py", line 1178, in _execute_text
    parameters,
  File "C:\Python 37\lib\site-packages\sqlalchemy\engine\base.py", line 1317, in _execute_context
    e, statement, parameters, cursor, context
  File "C:\Python 37\lib\site-packages\sqlalchemy\engine\base.py", line 1511, in _handle_dbapi_exception
    sqlalchemy_exception, with_traceback=exc_info[2], from_=e
  File "C:\Python 37\lib\site-packages\sqlalchemy\util\compat.py", line 182, in raise_
    raise exception
  File "C:\Python 37\lib\site-packages\sqlalchemy\engine\base.py", line 1277, in _execute_context
    cursor, statement, parameters, context
  File "C:\Python 37\lib\site-packages\sqlalchemy\engine\default.py", line 608, in do_execute
    cursor.execute(statement, parameters)
  File "C:\Python 37\lib\site-packages\pymysql\cursors.py", line 148, in execute
    result = self._query(query)
  File "C:\Python 37\lib\site-packages\pymysql\cursors.py", line 310, in _query
    conn.query(q)
  File "C:\Python 37\lib\site-packages\pymysql\connections.py", line 548, in query
    self._affected_rows = self._read_query_result(unbuffered=unbuffered)
  File "C:\Python 37\lib\site-packages\pymysql\connections.py", line 775, in _read_query_result
    result.read()
  File "C:\Python 37\lib\site-packages\pymysql\connections.py", line 1156, in read
    first_packet = self.connection._read_packet()
  File "C:\Python 37\lib\site-packages\pymysql\connections.py", line 725, in _read_packet
    packet.raise_for_error()
  File "C:\Python 37\lib\site-packages\pymysql\protocol.py", line 221, in raise_for_error
    err.raise_mysql_exception(self._data)
  File "C:\Python 37\lib\site-packages\pymysql\err.py", line 143, in raise_mysql_exception
    raise errorclass(errno, errval)
sqlalchemy.exc.IntegrityError: (pymysql.err.IntegrityError) (1062, "Duplicate entry '1-2-2021-09-28 00:00:00' for key 'main_table.PRIMARY'")
[SQL: 
                INSERT INTO skameyka.main_table (user_id, project_id, timestamp, hours) VALUES 
                (
                    (SELECT id FROM skameyka.user_table WHERE fullname like '“˛·‡Â‚ ¿Ú∏Ï'),
                    (SELECT id FROM skameyka.project_table WHERE title like '∆   ŒÃ‘Œ–“'),
                    '2021-09-28', 3
                )            
                ]
(Background on this error at: http://sqlalche.me/e/13/gkpj)
Traceback (most recent call last):
  File "C:\Python 37\lib\site-packages\sqlalchemy\engine\base.py", line 1277, in _execute_context
    cursor, statement, parameters, context
  File "C:\Python 37\lib\site-packages\sqlalchemy\engine\default.py", line 608, in do_execute
    cursor.execute(statement, parameters)
  File "C:\Python 37\lib\site-packages\pymysql\cursors.py", line 148, in execute
    result = self._query(query)
  File "C:\Python 37\lib\site-packages\pymysql\cursors.py", line 310, in _query
    conn.query(q)
  File "C:\Python 37\lib\site-packages\pymysql\connections.py", line 548, in query
    self._affected_rows = self._read_query_result(unbuffered=unbuffered)
  File "C:\Python 37\lib\site-packages\pymysql\connections.py", line 775, in _read_query_result
    result.read()
  File "C:\Python 37\lib\site-packages\pymysql\connections.py", line 1156, in read
    first_packet = self.connection._read_packet()
  File "C:\Python 37\lib\site-packages\pymysql\connections.py", line 725, in _read_packet
    packet.raise_for_error()
  File "C:\Python 37\lib\site-packages\pymysql\protocol.py", line 221, in raise_for_error
    err.raise_mysql_exception(self._data)
  File "C:\Python 37\lib\site-packages\pymysql\err.py", line 143, in raise_mysql_exception
    raise errorclass(errno, errval)
pymysql.err.IntegrityError: (1062, "Duplicate entry '1-2-2021-09-28 00:00:00' for key 'main_table.PRIMARY'")

The above exception was the direct cause of the following exception:

Traceback (most recent call last):
  File "C:\Users\Asus\PycharmProjects\SKAMEYKA\callback.py", line 200, in SaveCalendar
    con.execute(sql)
  File "C:\Python 37\lib\site-packages\sqlalchemy\engine\base.py", line 1003, in execute
    return self._execute_text(object_, multiparams, params)
  File "C:\Python 37\lib\site-packages\sqlalchemy\engine\base.py", line 1178, in _execute_text
    parameters,
  File "C:\Python 37\lib\site-packages\sqlalchemy\engine\base.py", line 1317, in _execute_context
    e, statement, parameters, cursor, context
  File "C:\Python 37\lib\site-packages\sqlalchemy\engine\base.py", line 1511, in _handle_dbapi_exception
    sqlalchemy_exception, with_traceback=exc_info[2], from_=e
  File "C:\Python 37\lib\site-packages\sqlalchemy\util\compat.py", line 182, in raise_
    raise exception
  File "C:\Python 37\lib\site-packages\sqlalchemy\engine\base.py", line 1277, in _execute_context
    cursor, statement, parameters, context
  File "C:\Python 37\lib\site-packages\sqlalchemy\engine\default.py", line 608, in do_execute
    cursor.execute(statement, parameters)
  File "C:\Python 37\lib\site-packages\pymysql\cursors.py", line 148, in execute
    result = self._query(query)
  File "C:\Python 37\lib\site-packages\pymysql\cursors.py", line 310, in _query
    conn.query(q)
  File "C:\Python 37\lib\site-packages\pymysql\connections.py", line 548, in query
    self._affected_rows = self._read_query_result(unbuffered=unbuffered)
  File "C:\Python 37\lib\site-packages\pymysql\connections.py", line 775, in _read_query_result
    result.read()
  File "C:\Python 37\lib\site-packages\pymysql\connections.py", line 1156, in read
    first_packet = self.connection._read_packet()
  File "C:\Python 37\lib\site-packages\pymysql\connections.py", line 725, in _read_packet
    packet.raise_for_error()
  File "C:\Python 37\lib\site-packages\pymysql\protocol.py", line 221, in raise_for_error
    err.raise_mysql_exception(self._data)
  File "C:\Python 37\lib\site-packages\pymysql\err.py", line 143, in raise_mysql_exception
    raise errorclass(errno, errval)
sqlalchemy.exc.IntegrityError: (pymysql.err.IntegrityError) (1062, "Duplicate entry '1-2-2021-09-28 00:00:00' for key 'main_table.PRIMARY'")
[SQL: 
                INSERT INTO skameyka.main_table (user_id, project_id, timestamp, hours) VALUES 
                (
                    (SELECT id FROM skameyka.user_table WHERE fullname like '“˛·‡Â‚ ¿Ú∏Ï'),
                    (SELECT id FROM skameyka.project_table WHERE title like '∆   ŒÃ‘Œ–“'),
                    '2021-09-28', 2
                )            
                ]
(Background on this error at: http://sqlalche.me/e/13/gkpj)
Traceback (most recent call last):
  File "C:\Python 37\lib\site-packages\sqlalchemy\engine\base.py", line 1277, in _execute_context
    cursor, statement, parameters, context
  File "C:\Python 37\lib\site-packages\sqlalchemy\engine\default.py", line 608, in do_execute
    cursor.execute(statement, parameters)
  File "C:\Python 37\lib\site-packages\pymysql\cursors.py", line 148, in execute
    result = self._query(query)
  File "C:\Python 37\lib\site-packages\pymysql\cursors.py", line 310, in _query
    conn.query(q)
  File "C:\Python 37\lib\site-packages\pymysql\connections.py", line 548, in query
    self._affected_rows = self._read_query_result(unbuffered=unbuffered)
  File "C:\Python 37\lib\site-packages\pymysql\connections.py", line 775, in _read_query_result
    result.read()
  File "C:\Python 37\lib\site-packages\pymysql\connections.py", line 1156, in read
    first_packet = self.connection._read_packet()
  File "C:\Python 37\lib\site-packages\pymysql\connections.py", line 725, in _read_packet
    packet.raise_for_error()
  File "C:\Python 37\lib\site-packages\pymysql\protocol.py", line 221, in raise_for_error
    err.raise_mysql_exception(self._data)
  File "C:\Python 37\lib\site-packages\pymysql\err.py", line 143, in raise_mysql_exception
    raise errorclass(errno, errval)
pymysql.err.IntegrityError: (1062, "Duplicate entry '1-1-2021-09-22 00:00:00' for key 'main_table.PRIMARY'")

The above exception was the direct cause of the following exception:

Traceback (most recent call last):
  File "C:\Users\Asus\PycharmProjects\SKAMEYKA\callback.py", line 205, in SaveCalendar
    con.execute(sql)
  File "C:\Python 37\lib\site-packages\sqlalchemy\engine\base.py", line 1003, in execute
    return self._execute_text(object_, multiparams, params)
  File "C:\Python 37\lib\site-packages\sqlalchemy\engine\base.py", line 1178, in _execute_text
    parameters,
  File "C:\Python 37\lib\site-packages\sqlalchemy\engine\base.py", line 1317, in _execute_context
    e, statement, parameters, cursor, context
  File "C:\Python 37\lib\site-packages\sqlalchemy\engine\base.py", line 1511, in _handle_dbapi_exception
    sqlalchemy_exception, with_traceback=exc_info[2], from_=e
  File "C:\Python 37\lib\site-packages\sqlalchemy\util\compat.py", line 182, in raise_
    raise exception
  File "C:\Python 37\lib\site-packages\sqlalchemy\engine\base.py", line 1277, in _execute_context
    cursor, statement, parameters, context
  File "C:\Python 37\lib\site-packages\sqlalchemy\engine\default.py", line 608, in do_execute
    cursor.execute(statement, parameters)
  File "C:\Python 37\lib\site-packages\pymysql\cursors.py", line 148, in execute
    result = self._query(query)
  File "C:\Python 37\lib\site-packages\pymysql\cursors.py", line 310, in _query
    conn.query(q)
  File "C:\Python 37\lib\site-packages\pymysql\connections.py", line 548, in query
    self._affected_rows = self._read_query_result(unbuffered=unbuffered)
  File "C:\Python 37\lib\site-packages\pymysql\connections.py", line 775, in _read_query_result
    result.read()
  File "C:\Python 37\lib\site-packages\pymysql\connections.py", line 1156, in read
    first_packet = self.connection._read_packet()
  File "C:\Python 37\lib\site-packages\pymysql\connections.py", line 725, in _read_packet
    packet.raise_for_error()
  File "C:\Python 37\lib\site-packages\pymysql\protocol.py", line 221, in raise_for_error
    err.raise_mysql_exception(self._data)
  File "C:\Python 37\lib\site-packages\pymysql\err.py", line 143, in raise_mysql_exception
    raise errorclass(errno, errval)
sqlalchemy.exc.IntegrityError: (pymysql.err.IntegrityError) (1062, "Duplicate entry '1-1-2021-09-22 00:00:00' for key 'main_table.PRIMARY'")
[SQL: 
                INSERT INTO skameyka.main_table (user_id, project_id, timestamp, hours) VALUES 
                (
                    (SELECT id FROM skameyka.user_table WHERE fullname like '“˛·‡Â‚ ¿Ú∏Ï'),
                    (SELECT id FROM skameyka.project_table WHERE title like 'œ–Œ≈ “ 1'),
                    '2021-09-22', 2
                )            
                ]
(Background on this error at: http://sqlalche.me/e/13/gkpj)
